Workbook
Name Slicer_B2B: #N/A
Name Slicer_Category: #N/A
Name Slicer_fulfilled_by: #N/A
Name Slicer_Order_status: #N/A
Name Slicer_ship_state: #N/A

Sheet Cleaned data
A1: Order ID | B1: Date | C1: Status | D1: Order status | E1: Fulfilment | F1: Sales Channel | G1: ship-service-level | H1: SKU | I1: Category | J1: Size | K1: Courier Status | L1: Qty | M1: Amount | N1: ship-city | O1: ship-state | P1: ship-country | Q1: B2B | R1: fulfilled-by
A2: 405-8078784-5731545 | B2: 44681 | C2: Cancelled | D2: =IF(Table1[[#This Row],[Status]]="Cancelled","Cancelled","Completed") -> Cancelled | E2: Merchant | F2: Amazon.in | G2: Standard | H2: SET389-KR-NP-S | I2: Set | J2: S | L2: 0 | M2: 647.62 | N2: MUMBAI | O2: MAHARASHTRA | P2: IN | Q2: FALSE | R2: Easy Ship
A3: 171-9198151-1101146 | B3: 44681 | C3: Shipped - Delivered to Buyer | D3: =IF(Table1[[#This Row],[Status]]="Cancelled","Cancelled","Completed") -> Completed | E3: Merchant | F3: Amazon.in | G3: Standard | H3: JNE3781-KR-XXXL | I3: kurta | J3: 3XL | K3: Shipped | L3: 1 | M3: 406 | N3: BENGALURU | O3: KARNATAKA | P3: IN | Q3: FALSE | R3: Easy Ship
A4: 404-0687676-7273146 | B4: 44681 | C4: Shipped | D4: =IF(Table1[[#This Row],[Status]]="Cancelled","Cancelled","Completed") -> Completed | E4: Amazon | F4: Amazon.in | G4: Expedited | H4: JNE3371-KR-XL | I4: kurta | J4: XL | K4: Shipped | L4: 1 | M4: 329 | N4: NAVI MUMBAI | O4: MAHARASHTRA | P4: IN | Q4: TRUE
A5: 403-9615377-8133951 | B5: 44681 | C5: Cancelled | D5: =IF(Table1[[#This Row],[Status]]="Cancelled","Cancelled","Completed") -> Cancelled | E5: Merchant | F5: Amazon.in | G5: Standard | H5: J0341-DR-L | I5: Western Dress | J5: L | L5: 0 | M5: 753.33 | N5: PUDUCHERRY | O5: PUDUCHERRY | P5: IN | Q5: FALSE | R5: Easy Ship
A6: 407-1069790-7240320 | B6: 44681 | C6: Shipped | D6: =IF(Table1[[#This Row],[Status]]="Cancelled","Cancelled","Completed") -> Completed | E6: Amazon | F6: Amazon.in | G6: Expedited | H6: JNE3671-TU-XXXL | I6: Top | J6: 3XL | K6: Shipped | L6: 1 | M6: 574 | N6: CHENNAI | O6: TAMIL NADU | P6: IN | Q6: FALSE
A7: 404-1490984-4578765 | B7: 44681 | C7: Shipped | D7: =IF(Table1[[#This Row],[Status]]="Cancelled","Cancelled","Completed") -> Completed | E7: Amazon | F7: Amazon.in | G7: Expedited | H7: SET264-KR-NP-XL | I7: Set | J7: XL | K7: Shipped | L7: 1 | M7: 824 | N7: GHAZIABAD | O7: UTTAR PRADESH | P7: IN | Q7: FALSE
A8: 408-5748499-6859555 | B8: 44681 | C8: Shipped | D8: =IF(Table1[[#This Row],[Status]]="Cancelled","Cancelled","Completed") -> Completed | E8: Amazon | F8: Amazon.in | G8: Expedited | H8: J0095-SET-L | I8: Set | J8: L | K8: Shipped | L8: 1 | M8: 653 | N8: CHANDIGARH | O8: CHANDIGARH | P8: IN | Q8: FALSE
A9: 406-7807733-3785945 | B9: 44681 | C9: Shipped - Delivered to Buyer | D9: =IF(Table1[[#This Row],[Status]]="Cancelled","Cancelled","Completed") -> Completed | E9: Merchant | F9: Amazon.in | G9: Standard | H9: JNE3405-KR-S | I9: kurta | J9: S | K9: Shipped | L9: 1 | M9: 399 | N9: HYDERABAD | O9: TELANGANA | P9: IN | Q9: FALSE | R9: Easy Ship
A10: 402-4393761-0311520 | B10: 44681 | C10: Shipped | D10: =IF(Table1[[#This Row],[Status]]="Cancelled","Cancelled","Completed") -> Completed | E10: Amazon | F10: Amazon.in | G10: Expedited | H10: JNE3461-KR-XXL | I10: kurta | J10: XXL | K10: Shipped | L10: 1 | M10: 363 | N10: Chennai | O10: TAMIL NADU | P10: IN | Q10: FALSE
A11: 407-5633625-6970741 | B11: 44681 | C11: Shipped | D11: =IF(Table1[[#This Row],[Status]]="Cancelled","Cancelled","Completed") -> Completed | E11: Amazon | F11: Amazon.in | G11: Expedited | H11: JNE3160-KR-G-S | I11: kurta | J11: S | K11: Shipped | L11: 1 | M11: 685 | N11: CHENNAI | O11: TAMIL NADU | P11: IN | Q11: FALSE
A12: 171-4638481-6326716 | B12: 44681 | C12: Shipped | D12: =IF(Table1[[#This Row],[Status]]="Cancelled","Cancelled","Completed") -> Completed | E12: Amazon | F12: Amazon.in | G12: Expedited | H12: JNE3500-KR-XS | I12: kurta | J12: XS | K12: Shipped | L12: 1 | M12: 364 | N12: NOIDA | O12: UTTAR PRADESH | P12: IN | Q12: FALSE
A13: 405-5513694-8146768 | B13: 44681 | C13: Shipped - Delivered to Buyer | D13: =IF(Table1[[#This Row],[Status]]="Cancelled","Cancelled","Completed") -> Completed | E13: Merchant | F13: Amazon.in | G13: Standard | H13: JNE3405-KR-XS | I13: kurta | J13: XS | K13: Shipped | L13: 1 | M13: 399 | N13: Amravati. | O13: MAHARASHTRA | P13: IN | Q13: FALSE | R13: Easy Ship
A14: 408-7955685-3083534 | B14: 44681 | C14: Shipped | D14: =IF(Table1[[#This Row],[Status]]="Cancelled","Cancelled","Completed") -> Completed | E14: Amazon | F14: Amazon.in | G14: Expedited | H14: SET182-KR-DH-XS | I14: Set | J14: XS | K14: Shipped | L14: 1 | M14: 657 | N14: MUMBAI | O14: MAHARASHTRA | P14: IN | Q14: FALSE
A15: 408-1298370-1920302 | B15: 44681 | C15: Shipped - Delivered to Buyer | D15: =IF(Table1[[#This Row],[Status]]="Cancelled","Cancelled","Completed") -> Completed | E15: Merchant | F15: Amazon.in | G15: Standard | H15: J0351-SET-L | I15: Set | J15: L | K15: Shipped | L15: 1 | M15: 771 | N15: MUMBAI | O15: MAHARASHTRA | P15: IN | Q15: FALSE | R15: Easy Ship
A16: 403-4965581-9520319 | B16: 44681 | C16: Shipped - Delivered to Buyer | D16: =IF(Table1[[#This Row],[Status]]="Cancelled","Cancelled","Completed") -> Completed | E16: Merchant | F16: Amazon.in | G16: Standard | H16: PJNE3368-KR-6XL | I16: kurta | J16: 6XL | K16: Shipped | L16: 1 | M16: 544 | N16: GUNTAKAL | O16: ANDHRA PRADESH | P16: IN | Q16: FALSE | R16: Easy Ship
A17: 406-9379318-6555504 | B17: 44681 | C17: Shipped | D17: =IF(Table1[[#This Row],[Status]]="Cancelled","Cancelled","Completed") -> Completed | E17: Amazon | F17: Amazon.in | G17: Expedited | H17: JNE3721-KR-XXL | I17: kurta | J17: XXL | K17: Shipped | L17: 1 | M17: 329 | N17: JAIPUR | O17: RAJASTHAN | P17: IN | Q17: FALSE
A18: 405-9013803-8009918 | B18: 44681 | C18: Shipped | D18: =IF(Table1[[#This Row],[Status]]="Cancelled","Cancelled","Completed") -> Completed | E18: Amazon | F18: Amazon.in | G18: Expedited | H18: JNE3405-KR-XL | I18: kurta | J18: XL | K18: Shipped | L18: 1 | M18: 399 | N18: NEW DELHI | O18: DELHI | P18: IN | Q18: FALSE
A19: 402-4030358-5835511 | B19: 44681 | C19: Shipped - Delivered to Buyer | D19: =IF(Table1[[#This Row],[Status]]="Cancelled","Cancelled","Completed") -> Completed | E19: Merchant | F19: Amazon.in | G19: Standard | H19: JNE3697-KR-XXL | I19: kurta | J19: XXL | K19: Shipped | L19: 1 | M19: 458 | N19: Gurgaon | O19: HARYANA | P19: IN | Q19: FALSE | R19: Easy Ship
A20: 405-5957858-1051546 | B20: 44681 | C20: Shipped | D20: =IF(Table1[[#This Row],[Status]]="Cancelled","Cancelled","Completed") -> Completed | E20: Amazon | F20: Amazon.in | G20: Expedited | H20: SET254-KR-NP-XS | I20: Set | J20: XS | K20: Shipped | L20: 1 | M20: 886 | N20: BENGALURU | O20: KARNATAKA | P20: IN | Q20: FALSE
A21: 405-0607769-0716360 | B21: 44681 | C21: Shipped | D21: =IF(Table1[[#This Row],[Status]]="Cancelled","Cancelled","Completed") -> Completed | E21: Amazon | F21: Amazon.in | G21: Expedited | H21: JNE3795-KR-XXXL | I21: kurta | J21: 3XL | K21: Shipped | L21: 1 | M21: 517 | N21: TIRUCHIRAPPALLI | O21: TAMIL NADU | P21: IN | Q21: FALSE
A22: 404-8494550-5860325 | B22: 44681 | C22: Shipped | D22: =IF(Table1[[#This Row],[Status]]="Cancelled","Cancelled","Completed") -> Completed | E22: Amazon | F22: Amazon.in | G22: Expedited | H22: SET345-KR-NP-M | I22: Set | J22: M | K22: Shipped | L22: 1 | M22: 666 | N22: BENGALURU | O22: KARNATAKA | P22: IN | Q22: FALSE
A23: 171-1305077-2813934 | B23: 44681 | C23: Shipped | D23: =IF(Table1[[#This Row],[Status]]="Cancelled","Cancelled","Completed") -> Completed | E23: Amazon | F23: Amazon.in | G23: Expedited | H23: JNE3373-KR-L | I23: kurta | J23: L | K23: Shipped | L23: 1 | M23: 376 | N23: HYDERABAD | O23: TELANGANA | P23: IN | Q23: FALSE
A24: 404-6019946-2909948 | B24: 44681 | C24: Cancelled | D24: =IF(Table1[[#This Row],[Status]]="Cancelled","Cancelled","Completed") -> Cancelled | E24: Merchant | F24: Amazon.in | G24: Standard | H24: SET291-KR-PP-M | I24: Set | J24: M | L24: 0 | M24: 570.48 | N24: pune | O24: MAHARASHTRA | P24: IN | Q24: FALSE | R24: Easy Ship
A25: 402-3384087-4005164 | B25: 44681 | C25: Shipped | D25: =IF(Table1[[#This Row],[Status]]="Cancelled","Cancelled","Completed") -> Completed | E25: Amazon | F25: Amazon.in | G25: Expedited | H25: MEN5002-KR-L | I25: kurta | J25: L | K25: Shipped | L25: 1 | M25: 499 | N25: TEZPUR | O25: ASSAM | P25: IN | Q25: FALSE
A26: 405-8191138-5176316 | B26: 44681 | C26: Shipped - Delivered to Buyer | D26: =IF(Table1[[#This Row],[Status]]="Cancelled","Cancelled","Completed") -> Completed | E26: Merchant | F26: Amazon.in | G26: Standard | H26: NW030-TP-PJ-XS | I26: Set | J26: XS | K26: Shipped | L26: 1 | M26: 582 | N26: RANCHI | O26: JHARKHAND | P26: IN | Q26: FALSE | R26: Easy Ship
A27: 403-9230474-9657916 | B27: 44681 | C27: Shipped - Delivered to Buyer | D27: =IF(Table1[[#This Row],[Status]]="Cancelled","Cancelled","Completed") -> Completed | E27: Merchant | F27: Amazon.in | G27: Standard | H27: JNE3415-KR-XXXL | I27: kurta | J27: 3XL | K27: Shipped | L27: 1 | M27: 299 | N27: BILASPUR | O27: CHHATTISGARH | P27: IN | Q27: FALSE | R27: Easy Ship
A28: 408-3484251-6901959 | B28: 44681 | C28: Shipped | D28: =IF(Table1[[#This Row],[Status]]="Cancelled","Cancelled","Completed") -> Completed | E28: Amazon | F28: Amazon.in | G28: Expedited | H28: PJNE2199-KR-N-4XL | I28: kurta | J28: 4XL | K28: Shipped | L28: 1 | M28: 459 | N28: PUNE | O28: MAHARASHTRA | P28: IN | Q28: FALSE
A29: 405-7755803-4729935 | B29: 44681 | C29: Shipped | D29: =IF(Table1[[#This Row],[Status]]="Cancelled","Cancelled","Completed") -> Completed | E29: Amazon | F29: Amazon.in | G29: Expedited | H29: JNE3567-KR-M | I29: kurta | J29: M | K29: Shipped | L29: 1 | M29: 399 | N29: BENGALURU | O29: KARNATAKA | P29: IN | Q29: FALSE
A30: 171-9040274-9291563 | B30: 44681 | C30: Shipped | D30: =IF(Table1[[#This Row],[Status]]="Cancelled","Cancelled","Completed") -> Completed | E30: Amazon | F30: Amazon.in | G30: Expedited | H30: J0341-DR-S | I30: Western Dress | J30: S | K30: Shipped | L30: 1 | M30: 791 | N30: THIRUVARUR | O30: TAMIL NADU | P30: IN | Q30: FALSE
A31: 403-7056319-0979561 | B31: 44681 | C31: Shipped | D31: =IF(Table1[[#This Row],[Status]]="Cancelled","Cancelled","Completed") -> Completed | E31: Amazon | F31: Amazon.in | G31: Expedited | H31: MEN5009-KR-XL | I31: kurta | J31: XL | K31: Shipped | L31: 1 | M31: 499 | N31: LUCKNOW | O31: UTTAR PRADESH | P31: IN | Q31: FALSE
A32: 404-9632124-1107550 | B32: 44681 | C32: Shipped - Delivered to Buyer | D32: =IF(Table1[[#This Row],[Status]]="Cancelled","Cancelled","Completed") -> Completed | E32: Merchant | F32: Amazon.in | G32: Standard | H32: J0011-LCD-M | I32: Set | J32: M | K32: Shipped | L32: 1 | M32: 1233 | N32: VISAKHAPATNAM | O32: ANDHRA PRADESH | P32: IN | Q32: FALSE | R32: Easy Ship
A33: 402-1465437-0579556 | B33: 44681 | C33: Shipped - Delivered to Buyer | D33: =IF(Table1[[#This Row],[Status]]="Cancelled","Cancelled","Completed") -> Completed | E33: Merchant | F33: Amazon.in | G33: Standard | H33: JNE3766-KR-M | I33: kurta | J33: M | K33: Shipped | L33: 1 | M33: 517 | N33: JEYPUR | O33: ODISHA | P33: IN | Q33: FALSE | R33: Easy Ship
A34: 404-7774085-3780319 | B34: 44681 | C34: Shipped | D34: =IF(Table1[[#This Row],[Status]]="Cancelled","Cancelled","Completed") -> Completed | E34: Amazon | F34: Amazon.in | G34: Expedited | H34: JNE3373-KR-XL | I34: kurta | J34: XL | K34: Shipped | L34: 1 | M34: 376 | N34: HYDERABAD | O34: TELANGANA | P34: IN | Q34: FALSE
A35: 402-2764952-1492318 | B35: 44681 | C35: Shipped - Delivered to Buyer | D35: =IF(Table1[[#This Row],[Status]]="Cancelled","Cancelled","Completed") -> Completed | E35: Merchant | F35: Amazon.in | G35: Standard | H35: MEN5001-KR-XL | I35: kurta | J35: XL | K35: Shipped | L35: 1 | M35: 499 | N35: LUCKNOW | O35: UTTAR PRADESH | P35: IN | Q35: FALSE | R35: Easy Ship
A36: 406-0272200-7784379 | B36: 44681 | C36: Shipped | D36: =IF(Table1[[#This Row],[Status]]="Cancelled","Cancelled","Completed") -> Completed | E36: Amazon | F36: Amazon.in | G36: Expedited | H36: SET345-KR-NP-L | I36: Set | J36: L | K36: Shipped | L36: 1 | M36: 666 | N36: CHENNAI | O36: TAMIL NADU | P36: IN | Q36: FALSE
A37: 403-4367956-2849158 | B37: 44681 | C37: Shipped | D37: =IF(Table1[[#This Row],[Status]]="Cancelled","Cancelled","Completed") -> Completed | E37: Amazon | F37: Amazon.in | G37: Expedited | H37: JNE3787-KR-S | I37: kurta | J37: S | K37: Shipped | L37: 1 | M37: 487 | N37: NEW DELHI | O37: DELHI | P37: IN | Q37: FALSE
A38: 403-4367956-2849158 | B38: 44681 | C38: Shipped | D38: =IF(Table1[[#This Row],[Status]]="Cancelled","Cancelled","Completed") -> Completed | E38: Amazon | F38: Amazon.in | G38: Expedited | H38: JNE3543-KR-S | I38: kurta | J38: S | K38: Shipped | L38: 1 | M38: 368 | N38: NEW DELHI | O38: DELHI | P38: IN | Q38: FALSE
A39: 403-4242957-8599555 | B39: 44681 | C39: Shipped | D39: =IF(Table1[[#This Row],[Status]]="Cancelled","Cancelled","Completed") -> Completed | E39: Amazon | F39: Amazon.in | G39: Expedited | H39: JNE3405-KR-L | I39: kurta | J39: L | K39: Shipped | L39: 1 | M39: 399 | N39: THIRUVANANTHAPURAM | O39: KERALA | P39: IN | Q39: FALSE
A40: 408-7165704-5643524 | B40: 44681 | C40: Shipped | D40: =IF(Table1[[#This Row],[Status]]="Cancelled","Cancelled","Completed") -> Completed | E40: Amazon | F40: Amazon.in | G40: Expedited | H40: J0211-DR-XXL | I40: Ethnic Dress | J40: XXL | K40: Shipped | L40: 1 | M40: 699 | N40: GREATER NOIDA | O40: UTTAR PRADESH | P40: IN | Q40: FALSE
...

Sheet KPI
A1: Column1 | B1: Column2
A2: Total Revenue | B2: =SUM('Cleaned data'!M:M) -> 180881.75
A3: Total Orders | B3: =COUNTA('Cleaned data'!A:A) -> 284
A4: Total Quantity sold | B4: =SUM('Cleaned data'!L:L) -> 275
A5: Cancelled orders | B5: =COUNTIF('Cleaned data'!D:D,"Cancelled") -> 16
A6: Completed Orders | B6: =COUNTIF('Cleaned data'!D:D,"Completed") -> 267
A7: Cancellation Rate | B7: =B5/B3 -> 0.056338028
A8: Average order value | B8: =AVERAGE('Cleaned data'!M:M) -> 639.15813

Sheet Category analysis
B5: Row Labels | C5: Sum of Amount
B6: Set | C6: 100277.61
B7: kurta | C7: 48460
B8: Western Dress | C8: 18959.33
B9: Top | C9: 11263.81
B10: Ethnic Dress | C10: 1544
B11: Bottom | C11: 377
B12: Grand Total | C12: 180881.75

Sheet Status analysis
B6: Row Labels | C6: Count of Order ID
B7: Cancelled | C7: 16
B8: Completed | C8: 267
B9: Grand Total | C9: 283

Sheet state analysis
B2: Row Labels | C2: Sum of Amount
B3: KARNATAKA | C3: 27149.35
B4: MAHARASHTRA | C4: 26778.1
B5: UTTAR PRADESH | C5: 16707
B6: TELANGANA | C6: 14093
B7: WEST BENGAL | C7: 13361
B8: TAMIL NADU | C8: 11818
B9: Gujarat | C9: 7275
B10: HARYANA | C10: 6444.04
B11: DELHI | C11: 6428
B12: BIHAR | C12: 6402
B13: Grand Total | C13: 136455.49

Sheet Fulfillment_Analysis
B2: Row Labels | C2: Sum of Amount
B3: (blank) | C3: 139811
B4: Easy Ship | C4: 41070.75
B5: Grand Total | C5: 180881.75

Sheet size analysis
B3: Row Labels | C3: Sum of Qty
B4: M | C4: 54
B5: S | C5: 44
B6: XL | C6: 42
B7: XXL | C7: 37
B8: L | C8: 37
B9: 3XL | C9: 32
B10: XS | C10: 23
B11: 6XL | C11: 3
B12: 4XL | C12: 2
B13: 5XL | C13: 1
B14: Grand Total | C14: 275

Sheet Top products analysis
B4: Row Labels | C4: Sum of Amount
B5: SET268-KR-NP-L | C5: 2364
B6: SET304-KR-DPT-XS | C6: 2230
B7: J0008-SKD-XXL | C7: 2130
B8: SET345-KR-NP-M | C8: 1918
B9: SET324-KR-NP-M | C9: 1791
B10: SET347-KR-NP-S | C10: 1704
B11: SET291-KR-PP-M | C11: 1696.48
B12: J0280-SKD-S | C12: 1463
B13: SET355-KR-PP-M | C13: 1399
B14: SET363-KR-NP-XXL | C14: 1338
B15: SET277-KR-NP-XXL | C15: 1338
B16: Grand Total | C16: 19371.48

Sheet B2B analysis
B4: Row Labels | C4: Count of Order ID
B5: Consumer orders | C5: 281
B6: Business orders | C6: 2
B7: Grand Total | C7: 283

Sheet Dashboard
